<?xml version='1.0' encoding='utf-8'?>

<!-- Sostituire i joint continuos con revolute e limiti finti-->

<robot name="urdf_assembly">

    <link name="base_link">
        <visual>
            <origin xyz="0 0 0" rpy="0 0 0"/>
            <geometry>
                <box size="0.01 0.01 0.01"/>
            </geometry>
        </visual>
    </link> 
    
    <link name="body">
        <inertial>
            <origin xyz="0.0 -0.036 -0.0082" rpy="0.0 0.0 0.0" />
            <mass value="0.1223" />
            <inertia ixx="5.91121e-05" iyy="7.75083e-06" izz="5.56796e-05" ixy="-8.991e-12" iyz="-1.287e-06" ixz="-1.43744e-12" />
        </inertial>
        <visual name="body_visual">
            <origin xyz="0.0 0.0 0.0" rpy="0.0 0.0 0.0" />
            <geometry>
                <mesh filename="package://exoskeletron_description/meshes/body.stl" scale="0.001 0.001 0.001" />
            </geometry>
        </visual>
        <collision name="body_collision">
            <origin xyz="0.0 0.0 0.0" rpy="0.0 0.0 0.0" />
            <geometry>
                <mesh filename="package://exoskeletron_description/meshes/body.stl" scale="0.001 0.001 0.001" />
            </geometry>
        </collision>
    </link>

    <link name="link_AC">
        <inertial>
            <origin xyz="0.0222 -0.008172 0.0" rpy="0.0 0.0 0.0" />
            <mass value="0.06234" />
            <inertia ixx="1.15274e-05" iyy="9.5782e-06" izz="2.01595e-05" ixy="6.5499e-06" iyz="7.12e-08" ixz="-4.923e-08" />
        </inertial>
        <visual name="link_AC_visual">
            <origin xyz="0.007356 0.008556 0.0" rpy="-2.9131 -1.5708 0.0" />
            <geometry>
                <mesh filename="package://exoskeletron_description/meshes/link_AC.stl" scale="0.001 0.001 0.001" />
            </geometry>
        </visual>
        <collision name="link_AC_collision">
            <origin xyz="0.007356 0.008556 0.0" rpy="-2.9131 -1.5708 0.0" />
            <geometry>
                <mesh filename="package://exoskeletron_description/meshes/link_AC.stl" scale="0.001 0.001 0.001" />
            </geometry>
        </collision>
    </link>

    <link name="rear_crank">
        <inertial>
            <origin xyz="0.01361 0.007049 -0.000762" rpy="0.0 0.0 0.0" />
            <mass value="0.02908" />
            <inertia ixx="1.70292e-06" iyy="3.98339e-06" izz="4.76408e-06" ixy="-1.7956e-06" iyz="-1.13744e-07" ixz="-2.04e-07" />
        </inertial>
        <visual name="rear_crank_visual">
            <origin xyz="0.0171 -0.0588 0.0" rpy="-2.8798 -1.5708 0.0" />
            <geometry>
                <mesh filename="package://exoskeletron_description/meshes/rear_crank.stl" scale="0.001 0.001 0.001" />
            </geometry>
        </visual>
        <collision name="rear_crank_collision">
            <origin xyz="0.0171 -0.0588 0.0" rpy="-2.8798 -1.5708 0.0" />
            <geometry>
                <mesh filename="package://exoskeletron_description/meshes/rear_crank.stl" scale="0.001 0.001 0.001" />
            </geometry>
        </collision>
    </link>

    <link name="connecting_rod">
        <inertial>
            <origin xyz="-0.006793 -0.03467 0.0" rpy="0.0 0.0 0.0" />
            <mass value="0.03844" />
            <inertia ixx="1.55767e-05" iyy="1.21347e-06" izz="1.663e-05" ixy="-2.90187e-06" iyz="0.0" ixz="0.0" />
        </inertial>
        <visual name="connecting_rod_visual">
            <origin xyz="-0.03087 -0.06882 0.0" rpy="-3.132 -1.5708 0.0" />
            <geometry>
                <mesh filename="package://exoskeletron_description/meshes/connecting_rod.stl" scale="0.001 0.001 0.001" />
            </geometry>
        </visual>
        <collision name="connecting_rod_collision">
            <origin xyz="-0.03087 -0.06882 0.0" rpy="-3.132 -1.5708 0.0" />
            <geometry>
                <mesh filename="package://exoskeletron_description/meshes/connecting_rod.stl" scale="0.001 0.001 0.001" />
            </geometry>
        </collision>
    </link>


<!--   JOINTS  -->


    <joint name="rev_crank" type="revolute">
        <origin xyz="0.0 -0.05876 -0.0008932" rpy="-3.1416 -1.5708 0.0" />
        <parent link="body" />
        <child link="rear_crank" />
        <axis xyz="0.0 0.0 1.0" />
        <limit lower="-3.1416" upper="3.1416" effort="1000000" velocity="1000000" />
    </joint>

    <joint name="body_fixed" type="fixed">
        <parent link="base_link"/>
        <child link="body"/>
        <origin xyz="0 0 0" rpy="0 0 0"/>
    </joint>

    <joint name="rev_body2linkAC" type="revolute">
        <origin xyz="0.0 0.006701 -0.0089853" rpy="-3.1416 -1.5708 0.0" />
        <parent link="body" />
        <child link="link_AC" />
        <axis xyz="0.0 0.0 1.0" />
        <limit lower="-3.1416" upper="3.1416" effort="1000000" velocity="1000000" />
    </joint>

    <joint name="rev_crank2shaft" type="revolute">
        <origin xyz="0.02981 0.01566 0.0" rpy="0.0 0.0 0.0" />
        <parent link="rear_crank" />
        <child link="connecting_rod" />
        <axis xyz="0.0 0.0 1.0" />
        <limit lower="-3.1416" upper="3.1416" effort="1000000" velocity="1000000" />
    </joint>




    <!-- IMPORTANTE: questi vincoli sono eliminati dall'urdf per poter caricare su pinocchio una struttura ad albero (catena cinematica aperta). 
        Per chiudere la catena si impiegano dei vincoli numerici. Tutto nel nodo exo_kniematics_node


    <joint name="rev_shaft2linkAC" type="revolute">
        <origin xyz="0.02446 0.01180 0.0" rpy="0.0 0.0 0.0" />
        <parent link="link_AC" />
        <child link="connecting_rod" />
        <axis xyz="0.0 0.0 1.0" />
        <limit lower="-3.1416" upper="3.1416" effort="1000000" velocity="1000000" />
    </joint>
    -->

</robot>
